Workbook

Sheet Sales
C1: Change the Date in the green cell only
D2: =TEXT(D$3,"yyyy") -> 2025 | E2: =TEXT(E$3,"yyyy") -> 2025 | F2: =TEXT(F$3,"yyyy") -> 2025 | G2: =TEXT(G$3,"yyyy") -> 2025 | H2: =TEXT(H$3,"yyyy") -> 2025 | I2: =TEXT(I$3,"yyyy") -> 2025 | J2: =TEXT(J$3,"yyyy") -> 2025 | K2: =TEXT(K$3,"yyyy") -> 2025 | ... ABF2: =TEXT(ABF$3,"yyyy") -> 2027
D3: 45658 | E3: =D3+1 -> 45659 | F3: =E3+1 -> 45660 | G3: =F3+1 -> 45661 | H3: =G3+1 -> 45662 | I3: =H3+1 -> 45663 | J3: =I3+1 -> 45664 | K3: =J3+1 -> 45665 | L3: =K3+1 -> 45666 | ... ABF3: =ABE3+1 -> 46388
D4: =TEXT(D3,"ddd") -> Wed | E4: =TEXT(E3,"ddd") -> Thu | F4: =TEXT(F3,"ddd") -> Fri | G4: =TEXT(G3,"ddd") -> Sat | H4: =TEXT(H3,"ddd") -> Sun | I4: =TEXT(I3,"ddd") -> Mon | J4: =TEXT(J3,"ddd") -> Tue | K4: =TEXT(K3,"ddd") -> Wed | ... ABF4: =TEXT(ABF3,"ddd") -> Fri
C5: 11 AM - 12 PM | D5: 2157.14 | E5: 950 | F5: 2433 | G5: 1017 | H5: 13461 | I5: 3326 | J5: 30582 | K5: 2157.14 | L5: 950 | M5: 2433 | N5: 1017 | O5: 13461 | P5: 3326 | Q5: 30582 | R5: 2157.14 | S5: 950 | T5: 2433 | U5: 1017 | V5: 13461 | W5: 3326 | X5: 30582 | Y5: 2157.14 | Z5: 950 | AA5: 2433 | AB5: 1017 | AC5: 13461 | AD5: 3326 | AE5: 30582 | AF5: 2157.14 | AG5: 950 | AH5: 2433 | AI5: 1017 | AJ5: 13461 | AK5: 3326 | AL5: 30582 | AM5: 2157.14 | AN5: 950 | AO5: 2433 | AP5: 1017 | AQ5: 13461 | AR5: 3326 | AS5: 30582 | AT5: 2157.14 | AU5: 950 | AV5: 2433 | AW5: 1017 | AX5: 13461 | AY5: 3326 | AZ5: 30582 | BA5: 2157.14 | BB5: 950 | BC5: 2433 | BD5: 1017 | BE5: 13461 | BF5: 3326 | BG5: 30582 | BH5: 2157.14 | BI5: 950 | BJ5: 2433 | BK5: 1017 | BL5: 13461 | BM5: 3326 | BN5: 30582 | BO5: 2157.14 | BP5: 950 | BQ5: 2433 | BR5: 1017 | BS5: 13461 | BT5: 3326 | BU5: 30582 | BV5: 2157.14 | BW5: 950 | BX5: 2433 | BY5: 1017 | BZ5: 13461 | CA5: 3326 | CB5: 30582 | CC5: 2157.14 | CD5: 950 | CE5: 2433 | CF5: 1017 | CG5: 13461 | CH5: 3326 | CI5: 30582 | CJ5: 2157.14 | CK5: 950 | CL5: 2433 | CM5: 1017 | CN5: 13461 | CO5: 3326 | CP5: 30582 | CQ5: 2157.14 | CR5: 950 | CS5: 2433 | CT5: 1017 | CU5: 13461 | CV5: 3326 | CW5: 30582 | CX5: 2157.14 | CY5: 950 | CZ5: 2433 | DA5: 1017 | DB5: 2433 | DC5: 3169.79 | DD5: 5324 | DE5: 3099 | DF5: 30622 | DG5: =66+5827 -> 5893 | DH5: 2918 | DI5: 39987 | DJ5: 28762 | DK5: 25806 | DL5: 3811 | DM5: 3038.1 | DN5: 4151 | DO5: 637 | DP5: 2621 | DQ5: =19+5616 -> 5635 | DR5: =21266.67+56976.76 -> 78243.43 | DS5: =1991+3254 -> 5245 | DT5: 2727 | DU5: 0 | DV5: 2021 | DW5: 8445 | DX5: 29919 | DY5: =676+11174 -> 11850 | DZ5: 3880 | EA5: 25596.69 | EB5: =18228+7368 -> 25596 | EC5: 1506 | ED5: 22080 | EE5: 1520 | EF5: =16709+24378 -> 41087 | EG5: 27281 | EH5: 4132.55 | EI5: 4380 | EJ5: 9095 | EK5: 4860 | EL5: =7595+41581 -> 49176 | EM5: 42068 | EN5: 21692 | EP5: 1605 | EQ5: 12256 | ER5: =28514+30593 -> 59107 | ES5: 28822 | ET5: 18958.11 | EU5: 29238.78 | EV5: 33197.49 | EW5: 0 | EX5: 3449 | EY5: 6886 | EZ5: 20152 | FA5: 10030 | FB5: 27546 | FC5: 9441.29 | FF5: 1380 | FG5: 1101 | FH5: 2495 | FI5: 3996 | FJ5: 1768 | FK5: 657 | FL5: 665 | FM5: 1166 | FN5: 14905 | FO5: 6683 | FP5: 3849 | FQ5: =5038+8103 -> 13141 | FR5: 570 | FS5: 1445 | FT5: 303 | FU5: =12152+50319 -> 62471 | FV5: 13767 | FW5: =3990+16540 -> 20530 | FX5: =19+5429 -> 5448 | FY5: 504 | FZ5: 2003 | GA5: 2568 | GB5: 4100 | GC5: =13064+15440 -> 28504 | GD5: 5167 | GE5: 23958 | GF5: 1761 | GG5: 4343 | GH5: 2690 | GI5: 22500 | GJ5: 16856 | GK5: =16709+5099 -> 21808 | GL5: 23641.9 | GM5: 664 | GN5: 1687 | GO5: 7418 | GP5: 702 | GQ5: =8546+17042 -> 25588 | GR5: 3972 | GS5: 33152.81 | GT5: 6873 | GU5: =25823+6879 -> 32702 | GV5: 2141 | GW5: 8425 | GX5: 30037 | GY5: =22178+497443 -> 519621 | GZ5: =5690+1510 -> 7200 | HA5: 2433 | HB5: 1017 | HC5: 11479 | HD5: 60038.96 | HE5: 12152 | HF5: =22280+26723 -> 49003 | HG5: 10316 | HH5: 647.36 | HI5: 6728 | HJ5: 610 | HK5: =22828+7294 -> 30122 | HL5: 1493 | HM5: 793 | HN5: 13007 | HO5: 1550 | HP5: 5562 | HQ5: 6076 | HR5: =16709+8144 -> 24853 | HS5: 51377 | HT5: 42902 | HU5: 21728 | HV5: 1511 | HW5: 5470 | HX5: 15743 | HY5: 53863 | HZ5: =11770+32589 -> 44359 | IA5: 13890 | IB5: 15563 | IC5: 2386 | ID5: 2825 | IE5: =11673+19856 -> 31529 | IF5: =4219+18549 -> 22768 | IG5: =2767+14300 -> 17067 | IH5: 2125 | II5: 19077 | IJ5: 1549 | IK5: 4869 | IL5: 30400 | IM5: 32958 | IN5: =1522+20543 -> 22065 | IO5: 6737 | IP5: =464+57931 -> 58395 | IQ5: 1443 | IR5: 2729 | IS5: 13461 | IT5: 9718 | IU5: 13461 | IV5: 950 | IW5: 7411 | IX5: 24018 | IY5: 2146 | IZ5: 17033 | JA5: =31900+4172 -> 36072 | JB5: =8326+25175 -> 33501 | JC5: =3132+47033 -> 50165 | JD5: =9895+60672.91 -> 70567.91 | JE5: =303+2613 -> 2916 | JF5: 5105 | JG5: 6815.24 | JH5: 4296 | JI5: 12151 | JJ5: =7319+25390 -> 32709 | JK5: =18515+10304 -> 28819 | JL5: 475 | JM5: 1174 | JN5: =14563.9+50332.82 -> 64896.72 | JO5: 3068 | JP5: 43789 | JQ5: 355 | JR5: 5119 | JS5: 2031 | JT5: 2574 | JU5: 31040 | JV5: 5038 | JW5: 30582 | JX5: 2157.14 | JY5: 950 | JZ5: 475 | KA5: 370 | KB5: 2391 | KC5: =12152+7629 -> 19781 | KD5: 43060 | KE5: =5261+11542 -> 16803 | KF5: 4883 | KG5: 4962 | KH5: 5323 | KI5: 23673 | KJ5: 29892 | KK5: 18721 | KL5: 11153 | KM5: 4862 | KO5: 2584 | KP5: =80629+17155 -> 97784 | KQ5: =1273+6700 -> 7973 | KR5: =15190+43991 -> 59181 | KS5: 28192 | KT5: 6939 | KU5: 5852 | KV5: =16709+1874 -> 18583 | KW5: 2280.95 | KX5: 12748 | KY5: 36769 | KZ5: =1110+24836 -> 25946 | LA5: 6549 | LB5: 2376.19 | LC5: 7943 | LD5: 2935 | LE5: =12152+22572 -> 34724 | LF5: 28539 | LG5: 30666 | LH5: 51838 | LI5: 0 | LJ5: 4232.82 | LK5: 6286.5 | LL5: =4800+5416.11 -> 10216.11 | LM5: =1909.52+797.14+23467.66 -> 26174.32 | LN5: 20956.54 | LO5: =17660.61+12949.36+0 -> 30609.97 | LP5: 2283.03 | LQ5: 1916.8 | LR5: 7045 | LS5: =2324+43650 -> 45974 | LT5: =2193.33+47431.59 -> 49624.92 | LU5: 2157.14 | LV5: 950 | LW5: 2433 | LX5: 1017 | LY5: 4657 | LZ5: 14600 | MA5: =8326+30543 -> 38869 | MB5: 9373 | MC5: =10076+47060 -> 57136 | MD5: 28758 | ME5: 170 | MF5: 23428 | MG5: 18140 | MH5: 20512 | MI5: =1777+53580 -> 55357 | MJ5: 24736 | MK5: 1621 | ML5: =1174+1074 -> 2248 | MM5: 6953 | MN5: 12313 | MO5: 1398 | MP5: 2157.14 | MQ5: 950 | MR5: 2433 | MS5: 1017 | MT5: 13461 | MU5: =18228+18838 -> 37066 | MV5: 37541.93 | MW5: 11425 | MY5: 313 | MZ5: 1539 | NA5: =7595+3821 -> 11416 | NB5: =20181+55092 -> 75273 | NC5: =2426+35048 -> 37474 | NE5: 8086 | NG5: 6112 | NH5: =55894+50085 -> 105979 | NI5: 1154 | NJ5: 9703 | NK5: 31747 | NL5: 21164 | NN5: 2663 | NO5: 21606 | NP5: 10934 | NQ5: =8278+12060 -> 20338 | NR5: 6885 | NS5: 13703 | NT5: 541 | NU5: 235 | NV5: =7585+4036 -> 11621 | NW5: 9557 | NX5: 18363 | NY5: 17256 | NZ5: 16701 | OA5: 475 | OB5: 436 | OC5: 23535 | OD5: =8452.38+15462.34 -> 23914.72 | OE5: 18418 | OF5: 3726 | OG5: 742 | OH5: 3260 | OI5: 2556.19 | OJ5: 4296.19 | OK5: 8135.33 | OL5: 42902.18 | OM5: 19.05 | ON5: 10222.34 | OO5: 3481.73 | OP5: 1712.38 | OQ5: 1467.54 | OR5: =24027.36+14867.71 -> 38895.07 | OS5: =27342.86+16167.12 -> 43509.98 | OT5: 0 | OU5: 0 | OV5: 0 | OW5: 5045.28 | OX5: 1140 | OY5: 11788.74 | OZ5: 25642.08 | PA5: 1985.45 | PB5: 0 | PC5: 0 | PD5: 637.14 | PE5: 0 | PF5: 5485 | PG5: 1474.89 | PH5: 1224.77 | PI5: 2207.36 | PJ5: 448 | PK5: 1016.71 | PL5: 503.81 | PM5: 1187.62 | PN5: =503.81+8052.39 -> 8556.2 | PO5: 7838.96 | PP5: =154.98+47826.58 -> 47981.56 | PQ5: 1046 | PR5: 1396 | PS5: 475.24 | PT5: 448.48 | PU5: 2357.15 | PV5: 2448 | PW5: 2923.02 | PX5: 995.41 | PY5: 2451.6 | PZ5: 2528.49 | QA5: 56519.21 | QB5: 2940.01 | QC5: 1330.56 | QD5: 985.63 | QE5: 0 | QF5: 0 | QG5: 1711.69 | QH5: 0 | QI5: 16293.51 | QJ5: 5339.47 | QK5: 3662.42 | QL5: 2538.79 | QM5: 22143.21 | QN5: 21703 | QO5: 2983 | QP5: =5845.97+47614.99 -> 53460.96 | QQ5: 37490.91 | QR5: 20340.45 | QS5: 2485.29 | QT5: 3775 | QU5: 5388.48 | QV5: =8934.03+1217.15 -> 10151.18 | QW5: 10027.8 | QX5: 12197.31 | QY5: 9003 | QZ5: 4629 | RA5: 1204.15 | RB5: =3985.71+14710.21 -> 18695.92 | RC5: 10755 | RD5: 6873 | RE5: 27649.6 | RF5: 6162 | RG5: 1113 | RH5: 34690 | RI5: 2784 | RJ5: 1371 | RK5: 37409 | RL5: =1356.19+52882.93 -> 54239.12 | RM5: 9923.73 | RN5: 154.98 | RO5: 246 | RP5: 4743 | RQ5: =8680+10186.07 -> 18866.07 | RR5: =2519.05+21730.75 -> 24249.8 | RS5: 18228.11 | RT5: 15021 | RU5: 1700 | RV5: 31714.28 | RW5: 8067.71 | RX5: 40809.01 | RY5: =14592.2+19435.77 -> 34027.97 | RZ5: 3310.82 | SA5: =25520+6827.35 -> 32347.35 | SB5: 0 | SC5: 38919.05 | SD5: =18251.52+41819.74 -> 60071.26 | SE5: =18251.52+41819.74 -> 60071.26 | SF5: =605.02+16758.1 -> 17363.12 | SG5: 11393.43
C6: 12 PM - 1 PM | D6: 4618 | E6: 6038 | F6: 3770 | G6: 3584 | H6: 6723 | I6: 5125 | J6: 20984 | K6: 4618 | L6: 6038 | M6: 3770 | N6: 3584 | O6: 6723 | P6: 5125 | Q6: 20984 | R6: 4618 | S6: 6038 | T6: 3770 | U6: 3584 | V6: 6723 | W6: 5125 | X6: 20984 | Y6: 4618 | Z6: 6038 | AA6: 3770 | AB6: 3584 | AC6: 6723 | AD6: 5125 | AE6: 20984 | AF6: 4618 | AG6: 6038 | AH6: 3770 | AI6: 3584 | AJ6: 6723 | AK6: 5125 | AL6: 20984 | AM6: 4618 | AN6: 6038 | AO6: 3770 | AP6: 3584 | AQ6: 6723 | AR6: 5125 | AS6: 20984 | AT6: 4618 | AU6: 6038 | AV6: 3770 | AW6: 3584 | AX6: 6723 | AY6: 5125 | AZ6: 20984 | BA6: 4618 | BB6: 6038 | BC6: 3770 | BD6: 3584 | BE6: 6723 | BF6: 5125 | BG6: 20984 | BH6: 4618 | BI6: 6038 | BJ6: 3770 | BK6: 3584 | BL6: 6723 | BM6: 5125 | BN6: 20984 | BO6: 4618 | BP6: 6038 | BQ6: 3770 | BR6: 3584 | BS6: 6723 | BT6: 5125 | BU6: 20984 | BV6: 4618 | BW6: 6038 | BX6: 3770 | BY6: 3584 | BZ6: 6723 | CA6: 5125 | CB6: 20984 | CC6: 4618 | CD6: 6038 | CE6: 3770 | CF6: 3584 | CG6: 6723 | CH6: 5125 | CI6: 20984 | CJ6: 4618 | CK6: 6038 | CL6: 3770 | CM6: 3584 | CN6: 6723 | CO6: 5125 | CP6: 20984 | CQ6: 4618 | CR6: 6038 | CS6: 3770 | CT6: 3584 | CU6: 6723 | CV6: 5125 | CW6: 20984 | CX6: 4618 | CY6: 6038 | CZ6: 3770 | DA6: 3584 | DB6: 3770 | DC6: 1159.92 | DD6: 19790 | DE6: 11891 | DF6: 15296 | DG6: 1418 | DH6: 3659 | DI6: 8936 | DJ6: 11017 | DK6: 34164 | DL6: 23019 | DM6: 9178.35 | DN6: 1225 | DO6: 1694 | DP6: 2523 | DQ6: 15037 | DR6: 27922.2 | DS6: 14168 | DT6: 2169 | DU6: 1583 | DV6: 10104 | DW6: 5046 | DX6: 8597 | DY6: 20120 | DZ6: 6201 | EA6: 34146 | EB6: 34145 | EC6: 1169 | ED6: 3679 | EE6: 3647 | EF6: 12378 | EG6: 36654 | EH6: 12294.02 | EI6: 2092 | EJ6: 7043 | EK6: 1253 | EL6: 19478 | EM6: 14906 | EN6: 5311 | EP6: 19 | EQ6: 27709 | ER6: 7722 | ES6: 4448 | ET6: 41064.49 | EU6: 11673.95 | EV6: 10384.95 | EW6: 769.52 | EX6: 6124 | EY6: 4362 | EZ6: 12809 | FA6: 26620 | FB6: 15252 | FC6: 3040.95 | FD6: 2843 | FF6: 2621 | FG6: 815 | FH6: 8106 | FI6: 3925 | FJ6: 7350 | FK6: 738 | FL6: 4209 | FM6: 14087 | FN6: 46037 | FO6: 22813 | FP6: 24606 | FQ6: 48584 | FR6: 2223 | FS6: 5504 | FT6: 20386 | FU6: 9431 | FV6: 33959 | FW6: 44460 | FX6: 16633 | FY6: 1510 | FZ6: 4075 | GA6: 23340 | GB6: 60041 | GC6: 34587 | GD6: 18334 | GE6: 84072 | GF6: 3808 | GG6: 7575 | GH6: 1611 | GI6: 2845 | GJ6: 12484 | GK6: 19228 | GL6: 4695.49 | GM6: 2031 | GN6: 20773 | GO6: 3877 | GP6: 13293 | GQ6: 36976 | GR6: 34913 | GS6: 31739.75 | GT6: 4268 | GU6: 31456 | GV6: 19284 | GW6: 9425 | GX6: 13974 | GY6: 34038 | GZ6: 27979 | HA6: 3770 | HB6: 3584 | HC6: 4301 | HD6: 12820 | HE6: 21255 | HF6: 18267 | HG6: 5293 | HH6: 310 | HI6: 2164 | HJ6: 4121 | HK6: 7745 | HL6: 1940 | HM6: 11452 | HN6: 23330 | HO6: 7681 | HP6: 13454 | HQ6: 17107 | HR6: 38465 | HS6: 39567 | HT6: 5825 | HU6: 6342 | HV6: 1169 | HW6: 2152 | HX6: 13812 | HY6: 34980 | HZ6: 40774 | IA6: 21926 | IB6: 33421 | IC6: 4347 | ID6: 4532 | IE6: 3840 | IF6: 18549 | IG6: 23407 | IH6: 5804 | II6: 29858 | IJ6: 313 | IK6: 9664 | IL6: 3951 | IM6: 27762 | IN6: 29355 | IO6: 3193 | IP6: 11141 | IQ6: 17946 | IR6: 6920 | IS6: 6723 | IT6: =7322+475 -> 7797 | IU6: 6723 | IV6: 6038 | IW6: 6438 | IX6: 0 | IY6: 5241 | IZ6: 3044 | JA6: 11101 | JB6: 27525 | JC6: 56141 | JD6: 9318 | JE6: 1314 | JF6: 5076 | JG6: 2443.28 | JH6: 4674 | JI6: 26169 | JJ6: 43313 | JK6: 12655 | JL6: 3431 | JM6: 2758 | JN6: 3343.9 | JO6: 15519 | JP6: 28684 | JQ6: 2324 | JR6: 5058 | JS6: 1147 | JT6: 11393 | JU6: 6822 | JV6: 11558 | JW6: 20984 | JX6: 4618 | JY6: 6038 | JZ6: 1169 | KA6: 1853 | KB6: 28818 | KC6: 27869 | KD6: 30882 | KE6: 71534 | KF6: 3941 | KG6: 2493 | KH6: 4837 | KI6: 7883 | KJ6: 12066 | KK6: 16949 | KL6: 9704 | KM6: 6037 | KN6: 4959 | KO6: 3858 | KP6: 4003 | KQ6: 55361 | KR6: 15895 | KS6: 5116 | KT6: 15325 | KU6: 5687 | KV6: 18428 | KW6: 20591.51 | KX6: 7585 | KY6: 32863 | KZ6: 46536 | LA6: 25849 | LB6: 4513.76 | LC6: 7116 | LD6: 159674 | LE6: 15047 | LF6: 26600 | LG6: 4933 | LH6: 11417 | LI6: 682.86 | LJ6: 2205.29 | LK6: 12340.79 | LL6: 29831.54 | LM6: 12395.53 | LN6: 7560.79 | LO6: 35489.53 | LP6: 4573.34 | LQ6: 7567.72 | LR6: 25534 | LS6: 3658 | LT6: 15526.34 | LU6: 4618 | LV6: 6038 | LW6: 3770 | LX6: 3584 | LY6: 2854 | LZ6: 10575 | MA6: 20644 | MB6: 34709 | MC6: 44437 | MD6: 2701 | ME6: 4027 | MF6: 23181 | MG6: 27696 | MH6: 18292 | MI6: 6395 | MJ6: 3988 | MK6: 4397 | ML6: 4940 | MM6: 6507 | MN6: 5876 | MO6: 4933 | MP6: 4618 | MQ6: 6038 | MR6: 3770 | MS6: 3584 | MT6: 6723 | MU6: 8838 | MV6: 9856 | MW6: 15844 | MX6: 1415 | MY6: 2099 | MZ6: 2193 | NA6: 56991 | NB6: 5776 | NC6: 11353 | ND6: 9375 | NE6: 33196 | NF6: 5920 | NG6: 3749 | NH6: 4718 | NI6: 9234 | NJ6: 10484 | NK6: 46270 | NL6: 6112 | NM6: 4078 | NN6: 8539 | NO6: 11539 | NP6: 6092 | NQ6: 12211 | NR6: 9574 | NS6: 5117 | NT6: 6663 | NU6: 5270 | NV6: 18027 | NW6: 24317 | NX6: 51251 | NY6: 9614 | NZ6: 9946 | OA6: 1386 | OB6: 4597 | OC6: 47695 | OD6: 7155.41 | OE6: 31251 | OF6: 9617 | OG6: 45122 | OH6: 898 | OI6: 6428.05 | OJ6: 5074.19 | OK6: 12823.38 | OL6: 13745.05 | OM6: 1062.25 | ON6: 53423.83 | OO6: 1475.15 | OP6: 3866.67 | OQ6: 16214.03 | OR6: 9662.53 | OS6: 16652.15 | OT6: 5948.57 | OU6: 0 | OV6: 1755.59 | OW6: 702.86 | OX6: 3317.23 | OY6: 12661.37 | OZ6: 19929.26 | PA6: 3118.02 | PB6: 0 | PC6: 3004.69 | PD6: 399.05 | PE6: 309.95 | PF6: 6165 | PG6: 3109.53 | PH6: 4064.25 | PI6: 11058 | PJ6: 1580 | PK6: 733.07 | PL6: 1677.57 | PM6: 7680.87 | PN6: 10536.37 | PO6: 5913.51 | PP6: 13998.86 | PQ6: 494 | PR6: 5561 | PS6: 4256.02 | PT6: 6270.67 | PU6: 13836.7 | PV6: 3562 | PW6: 9175.06 | PX6: 475.24 | PY6: 6485.63 | PZ6: 5500.87 | QA6: 21940.95 | QB6: 1263.99 | QC6: 843.12 | QD6: 587.01 | QE6: 0 | QF6: 0 | QG6: 911.43 | QH6: 0 | QI6: 18278.27 | QJ6: 6330.31 | QK6: 3508.31 | QL6: 1426.41 | QM6: 4134.8 | QN6: 12633 | QO6: 40257 | QP6: 19758.79 | QQ6: 21474.12 | QR6: 21160 | QS6: 2583.81 | QT6: 6583 | QU6: 8645.72 | QV6: 42481.64 | QW6: 19286.59 | QX6: 23147.72 | QY6: 18598 | QZ6: 4465 | RA6: 6885.37 | RB6: 14498.61 | RC6: 28024 | RD6: 8446 | RE6: 6330.91 | RF6: 28236 | RG6: 2275 | RH6: 7297 | RI6: 24154 | RJ6: 28094 | RK6: 16023 | RL6: 9186.59 | RM6: 19162.46 | RN6: 4853.16 | RO6: 4211 | RP6: 11405 | RQ6: 10284.16 | RR6: 25025.37 | RS6: 5493.51 | RT6: 4805 | RU6: 657 | RV6: 6655.93 | RW6: 10832.56 | RX6: 28246.24 | RY6: 60088.41 | RZ6: 8246.84 | SA6: 8612.11 | SB6: 1130.48 | SC6: 18195.24 | SD6: 27845.29 | SE6: 27845.29 | SF6: 40259.15 | SG6: 8477.04
C7: 1 PM - 2 PM | D7: 14363 | E7: 6150 | F7: 10080 | G7: 5904 | H7: 4353 | I7: 9897 | J7: 23146 | K7: 14363 | L7: 6150 | M7: 10080 | N7: 5904 | O7: 4353 | P7: 9897 | Q7: 23146 | R7: 14363 | S7: 6150 | T7: 10080 | U7: 5904 | V7: 4353 | W7: 9897 | X7: 23146 | Y7: 14363 | Z7: 6150 | AA7: 10080 | AB7: 5904 | AC7: 4353 | AD7: 9897 | AE7: 23146 | AF7: 14363 | AG7: 6150 | AH7: 10080 | AI7: 5904 | AJ7: 4353 | AK7: 9897 | AL7: 23146 | AM7: 14363 | AN7: 6150 | AO7: 10080 | AP7: 5904 | AQ7: 4353 | AR7: 9897 | AS7: 23146 | AT7: 14363 | AU7: 6150 | AV7: 10080 | AW7: 5904 | AX7: 4353 | AY7: 9897 | AZ7: 23146 | BA7: 14363 | BB7: 6150 | BC7: 10080 | BD7: 5904 | BE7: 4353 | BF7: 9897 | BG7: 23146 | BH7: 14363 | BI7: 6150 | BJ7: 10080 | BK7: 5904 | BL7: 4353 | BM7: 9897 | BN7: 23146 | BO7: 14363 | BP7: 6150 | BQ7: 10080 | BR7: 5904 | BS7: 4353 | BT7: 9897 | BU7: 23146 | BV7: 14363 | BW7: 6150 | BX7: 10080 | BY7: 5904 | BZ7: 4353 | CA7: 9897 | CB7: 23146 | CC7: 14363 | CD7: 6150 | CE7: 10080 | CF7: 5904 | CG7: 4353 | CH7: 9897 | CI7: 23146 | CJ7: 14363 | CK7: 6150 | CL7: 10080 | CM7: 5904 | CN7: 4353 | CO7: 9897 | CP7: 23146 | CQ7: 14363 | CR7: 6150 | CS7: 10080 | CT7: 5904 | CU7: 4353 | CV7: 9897 | CW7: 23146 | CX7: 14363 | CY7: 6150 | CZ7: 10080 | DA7: 5904 | DB7: 10080 | DC7: 4738.94 | DD7: 30543 | DE7: 1825 | DF7: 8679 | DG7: 2146 | DH7: 4364 | DI7: 27976 | DJ7: 8754 | DK7: 56091 | DL7: 11418 | DM7: 4329 | DN7: 19438 | DO7: 3404 | DP7: 8207 | DQ7: 13851 | DR7: 18990 | DS7: 19607 | DT7: 9095 | DU7: 322 | DV7: 6556 | DW7: 4760 | DX7: 11919 | DY7: 26855 | DZ7: 9264 | EA7: 15166 | EB7: 15166 | EC7: 475 | ED7: 5058 | EE7: 11512 | EF7: 17613 | EG7: 32160 | EH7: 19847.8 | EI7: 6478 | EJ7: 22189 | EK7: 11594 | EL7: 11001 | EM7: 20367 | EN7: 18040 | EO7: 20572 | EP7: 6284 | EQ7: 9583 | ER7: 12837 | ES7: 6355 | ET7: 19917.35 | EU7: 10137.06 | EV7: 12920.45 | EW7: 23778.88 | EX7: 7105 | EY7: 13399 | EZ7: 6642 | FA7: 45433 | FB7: 27929 | FC7: 4510.9 | FD7: 2879 | FF7: 1533 | FG7: 5941 | FH7: 10849 | FI7: 7829 | FJ7: 10981 | FK7: 824 | FL7: 11905 | FM7: 14733 | FN7: 11946 | FO7: 19683 | FP7: 28451 | FQ7: 52677 | FR7: 4754 | FS7: 10942 | FT7: 13158 | FU7: 32885 | FV7: 24426 | FW7: 10590 | FX7: 16504 | FY7: 3398 | FZ7: 14485 | GA7: 14054 | GB7: 18941 | GC7: 26255 | GD7: 12043 | GE7: 13150 | GF7: 4373 | GG7: 13713 | GH7: 4999 | GI7: 10833 | GJ7: 28403 | GK7: 21329 | GL7: 21788.39 | GM7: 1196 | GN7: 11484 | GO7: 19268 | GP7: 12467 | GQ7: 21811 | GR7: 12448 | GS7: 13445.8 | GT7: 2846 | GU7: 8749 | GV7: 8975 | GW7: 11370 | GX7: 19895 | GY7: 13663 | GZ7: 9197 | HA7: 10080 | HB7: 5904 | HC7: 8179 | HD7: 19041 | HE7: 27483 | HF7: 17018 | HG7: 11848 | HH7: 6569 | HI7: 14098 | HJ7: 6039 | HK7: 16600 | HL7: 16358 | HM7: 41514 | HN7: 50288 | HO7: 547 | HP7: 6721 | HQ7: 5476 | HR7: 7936 | HS7: 21702 | HT7: 36348 | HU7: 25963 | HV7: 2386 | HW7: 8399 | HX7: 7597 | HY7: 18290 | HZ7: 21476 | IA7: 15819 | IB7: 23276 | IC7: 3227 | ID7: 11175 | IE7: 20332 | IF7: 8826 | IG7: 38932 | IH7: 8684 | II7: 19953 | IJ7: 7477 | IK7: 9474 | IL7: 6309 | IM7: 14262 | IN7: 350598 | IO7: 10232 | IP7: 10912 | IQ7: 3758 | IR7: 8283 | IS7: 4353 | IT7: 6150 | IU7: 11633 | IV7: =940+29837 -> 30777 | IW7: 17783 | IX7: 2568 | IY7: 12304 | IZ7: 14882 | JA7: 22516 | JB7: 116876 | JC7: 19813 | JD7: 22349 | JE7: 28686 | JF7: 13358 | JG7: 9297.58 | JH7: 35716 | JI7: 20263 | JJ7: 13410 | JK7: 15872 | JL7: 9288 | JM7: 7297 | JN7: 16822.07 | JO7: 27211 | JP7: 39462 | JQ7: 1633 | JR7: 4391 | JS7: 2443 | JT7: 10236 | JU7: 21493 | JV7: 2878 | JW7: 23146 | JX7: 14363 | JY7: 6150 | JZ7: 4555 | KA7: 9364 | KB7: 12981 | KC7: 17038 | KD7: 18519 | KE7: 16031 | KF7: 19082 | KG7: 4774 | KH7: 11242 | KI7: 28255 | KJ7: 37317 | KK7: 24574 | KL7: 21715 | KM7: 25316 | KN7: 1132 | KO7: 9399 | KP7: 15009 | KQ7: 19916 | KR7: 55259 | KS7: 11028 | KT7: 11208 | KU7: 5071 | KV7: 4652 | KW7: 5285.02 | KX7: 19613 | KY7: 26186 | KZ7: 17819 | LA7: 87235 | LB7: 6706.61 | LC7: 14419 | LD7: 22607 | LE7: 13429 | LF7: 17795 | LG7: 36749 | LH7: 7006 | LI7: 2172.99 | LJ7: 13887.27 | LK7: 10089.87 | LL7: 31454.71 | LM7: 20024.93 | LN7: 17320.87 | LO7: 9937.41 | LP7: 5135.42 | LQ7: 8857.49 | LR7: 20872 | LS7: 7528 | LT7: 17265.81 | LU7: 14363 | LV7: 6150 | LW7: 10080 | LX7: 5904 | LY7: 9199 | LZ7: 12749 | MA7: 45729 | MB7: 9197 | MC7: 20328 | MD7: 2421 | ME7: 19300 | MF7: 25148 | MG7: 13719 | MH7: 19742 | MI7: 14141 | MJ7: 20532 | MK7: 4452 | ML7: 14252 | MM7: 39120 | MN7: 15749 | MO7: 8900 | MP7: 14363 | MQ7: 6150 | MR7: 10080 | MS7: 5904 | MT7: 4353 | MU7: 14799 | MV7: 43773 | MW7: 13641 | MX7: 7481 | MY7: 4025 | MZ7: 10645 | NA7: 20542 | NB7: 17589 | NC7: 16025 | ND7: 6176 | NE7: 11719 | NF7: 7540 | NG7: 5863 | NH7: 10417 | NI7: 15496 | NJ7: 23442 | NK7: 7312 | NL7: 21238 | NM7: 2743 | NN7: 11611 | NO7: 36549 | NP7: 21496 | NQ7: 33588 | NR7: 12562 | NS7: 15447 | NT7: 5660 | NU7: 16992 | NV7: 15817 | NW7: 15026 | NX7: 22776 | NY7: 18738 | NZ7: 10179 | OA7: 2132 | OB7: 9783 | OC7: 23758 | OD7: 9160.42 | OE7: 19107 | OF7: 14070 | OG7: 4218 | OH7: 845 | OI7: 9281.39 | OJ7: 2119.05 | OK7: 17864.6 | OL7: 19688.31 | OM7: 2021.13 | ON7: 8750.17 | OO7: 1793.59 | OP7: 9835.33 | OQ7: 6743.19 | OR7: 9701.57 | OS7: 29291.54 | OT7: 5988.33 | OU7: 0 | OV7: 1627.36 | OW7: 8575.15 | OX7: 12149.01 | OY7: 10420.63 | OZ7: 16799.76 | PA7: 15333 | PB7: 10325.79 | PC7: 3926.67 | PD7: 1609.27 | PE7: 2306.67 | PF7: 6550 | PG7: 8599.94 | PH7: 1839.32 | PI7: 31975 | PJ7: 5245 | PK7: 2338.79 | PL7: 7464.08 | PM7: 2723.3 | PN7: 9682.18 | PO7: 6551.43 | PP7: 31230.4 | PQ7: 1428 | PR7: 6239 | PS7: 13438.28 | PT7: 6108.14 | PU7: 18074.55 | PV7: 9706 | PW7: 9036.62 | PX7: 4076.89 | PY7: 6745.89 | PZ7: 5434.98 | QA7: 13086.89 | QB7: 9359.73 | QC7: 2616.62 | QD7: 3856.01 | QE7: 0 | QF7: 0 | QG7: 1702.68 | QH7: 1923.04 | QI7: 24007.04 | QJ7: 8826.41 | QK7: 3614.46 | QL7: 2178.44 | QM7: 4483.28 | QN7: 50962 | QO7: 13606 | QP7: 26412.26 | QQ7: 17523.2 | QR7: 9881.39 | QS7: 2126.33 | QT7: 10919 | QU7: 10199.65 | QV7: 20028.24 | QW7: 14435.61 | QX7: 10477.6 | QY7: 34002 | QZ7: 8930 | RA7: 6332.74 | RB7: 10176.74 | RC7: 9584 | RD7: 17405 | RE7: 8122.07 | RF7: 13251 | RG7: 6126 | RH7: 22860 | RI7: 8104 | RJ7: 16705 | RK7: 22683 | RL7: 11047.37 | RM7: 20919.24 | RN7: 3625.28 | RO7: 8023 | RP7: 28307 | RQ7: 35629.63 | RR7: 63547.75 | RS7: 10975.93 | RT7: 24458 | RU7: 4655 | RV7: 5712.47 | RW7: 30116.36 | RX7: 13907.03 | RY7: 27664.8 | RZ7: 58491.24 | SA7: 55770.55 | SB7: 6523.19 | SC7: 10443.3 | SD7: 14793.18 | SE7: 14793.18 | SF7: 20110.91 | SG7: 26679.15
C8: 2 PM - 3 PM | D8: 21740 | E8: 12216 | F8: 3219 | G8: 7899 | H8: 12211 | I8: 11103 | J8: 24511 | K8: 21740 | L8: 12216 | M8: 3219 | N8: 7899 | O8: 12211 | P8: 11103 | Q8: 24511 | R8: 21740 | S8: 12216 | T8: 3219 | U8: 7899 | V8: 12211 | W8: 11103 | X8: 24511 | Y8: 21740 | Z8: 12216 | AA8: 3219 | AB8: 7899 | AC8: 12211 | AD8: 11103 | AE8: 24511 | AF8: 21740 | AG8: 12216 | AH8: 3219 | AI8: 7899 | AJ8: 12211 | AK8: 11103 | AL8: 24511 | AM8: 21740 | AN8: 12216 | AO8: 3219 | AP8: 7899 | AQ8: 12211 | AR8: 11103 | AS8: 24511 | AT8: 21740 | AU8: 12216 | AV8: 3219 | AW8: 7899 | AX8: 12211 | AY8: 11103 | AZ8: 24511 | BA8: 21740 | BB8: 12216 | BC8: 3219 | BD8: 7899 | BE8: 12211 | BF8: 11103 | BG8: 24511 | BH8: 21740 | BI8: 12216 | BJ8: 3219 | BK8: 7899 | BL8: 12211 | BM8: 11103 | BN8: 24511 | BO8: 21740 | BP8: 12216 | BQ8: 3219 | BR8: 7899 | BS8: 12211 | BT8: 11103 | BU8: 24511 | BV8: 21740 | BW8: 12216 | BX8: 3219 | BY8: 7899 | BZ8: 12211 | CA8: 11103 | CB8: 24511 | CC8: 21740 | CD8: 12216 | CE8: 3219 | CF8: 7899 | CG8: 12211 | CH8: 11103 | CI8: 24511 | CJ8: 21740 | CK8: 12216 | CL8: 3219 | CM8: 7899 | CN8: 12211 | CO8: 11103 | CP8: 24511 | CQ8: 21740 | CR8: 12216 | CS8: 3219 | CT8: 7899 | CU8: 12211 | CV8: 11103 | CW8: 24511 | CX8: 21740 | CY8: 12216 | CZ8: 3219 | DA8: 7899 | DB8: 3219 | DC8: 5003 | DD8: 17139 | DE8: 2601 | DF8: 13946 | DG8: 3876 | DH8: 9323 | DI8: 20709 | DJ8: 4373 | DK8: 16496 | DL8: 12026 | DM8: 13935 | DN8: 4894 | DO8: 11332 | DP8: 6998 | DQ8: 8031 | DR8: 18488 | DS8: 15577 | DT8: 9990 | DU8: 2279 | DV8: 7099 | DW8: 8104 | DX8: 15134 | DY8: 19053 | DZ8: 14574 | EA8: 14535 | EB8: 14536 | EC8: 1658 | ED8: 8033 | EE8: 6240 | EF8: 26141 | EG8: 21868 | EH8: 13406.49 | EI8: 7648 | EJ8: 10737 | EK8: 6452 | EL8: 13780 | EM8: 27764 | EN8: 13472 | EO8: 61403 | EP8: 8668 | EQ8: 15895 | ER8: 34987 | ES8: 17902 | ET8: 1869.91 | EU8: 22164.17 | EV8: 18549.64 | EW8: 5221.14 | EX8: 12411 | EY8: 13561 | EZ8: 15751 | FA8: 25885 | FB8: 21764 | FC8: 6217.24 | FD8: 4297 | FE8: 940 | FF8: 1928 | FG8: 6186 | FH8: 17375 | FI8: 4651 | FJ8: 5973 | FK8: 6204 | FL8: 10589 | FM8: 21114 | FN8: 11321 | FO8: 29953 | FP8: 30213 | FQ8: 75233 | FR8: 3019 | FS8: 11843 | FT8: 6189 | FU8: 22839 | FV8: 27611 | FW8: 8751 | FX8: 29985 | FY8: 8735 | FZ8: 9586 | GA8: 12682 | GB8: 19782 | GC8: 28899 | GD8: 9584 | GE8: 29009 | GF8: 4400 | GG8: 8433 | GH8: 4214 | GI8: 25382 | GJ8: 26495 | GK8: 22860 | GL8: 41446.52 | GM8: 5017 | GN8: 9662 | GO8: 43149 | GP8: 7188 | GQ8: 24987 | GR8: 18175 | GS8: 8447.28 | GT8: 4940 | GU8: 11837 | GV8: 7541 | GW8: 16668 | GX8: 28681 | GY8: 19457 | GZ8: 11800 | HA8: 3219 | HB8: 7899 | HC8: 9955 | HD8: 16180 | HE8: 30756 | HF8: 9003 | HG8: 34103 | HH8: 8178 | HI8: 9357 | HJ8: 15671 | HK8: 16882 | HL8: 10782 | HM8: 16184 | HN8: 29102 | HO8: 6560 | HP8: 12807 | HQ8: 39427 | HR8: 27035 | HS8: 31063 | HT8: 10623 | HU8: 13488 | HV8: 3582 | HW8: 7400 | HX8: 15367 | HY8: 16520 | HZ8: 26025 | IA8: 36114 | IB8: 25129 | IC8: 3803 | ID8: 15061 | IE8: 18727 | IF8: 7773 | IG8: 31473 | IH8: 14218 | II8: 28531 | IJ8: 7951 | IK8: 13654 | IL8: 27754 | IM8: 15339 | IN8: 30774 | IO8: 25010 | IP8: 8154 | IQ8: 6528 | IR8: 10028 | IS8: 12211 | IT8: 12216 | IU8: 28165 | IV8: 18515 | IW8: 71620 | IX8: 9723 | IY8: 16340 | IZ8: 7776 | JA8: 21525 | JB8: 30770 | JC8: 13929 | JD8: 16817 | JE8: 1711 | JF8: 8113 | JG8: 18224.7 | JH8: 19660 | JI8: 40068 | JJ8: 28697 | JK8: 34526 | JL8: 7230 | JM8: 12738 | JN8: 35863.76 | JO8: 17028 | JP8: 23708 | JQ8: 4844 | JR8: 3815 | JS8: 9492 | JT8: 12716 | JU8: 11890 | JV8: 10298 | JW8: 24511 | JX8: 21740 | JY8: 12216 | JZ8: 5474 | KA8: 17146 | KB8: 20639 | KC8: =3545+2558 -> 6103 | KD8: 27292 | KE8: 15217 | KF8: 40240 | KG8: 6564 | KH8: 12433 | KI8: 14488 | KJ8: 66704 | KK8: 39445 | KL8: 8677 | KM8: 22586 | KN8: 5976 | KO8: 12438 | KP8: 6833 | KQ8: 24578 | KR8: 28547 | KS8: 23294 | KT8: 14232 | KU8: 6278 | KV8: 8494 | KW8: 6755.06 | KX8: 19866 | KY8: 21975 | KZ8: 11878 | LA8: 22300 | LB8: 10244.68 | LC8: 18882 | LD8: 10006 | LE8: 21455 | LF8: 17817 | LG8: 11524 | LH8: 6318 | LI8: 4948.76 | LJ8: 16266.14 | LK8: 14391.38 | LL8: 11617.67 | LM8: 25458.98 | LN8: 21475.32 | LO8: 7522.34 | LP8: 5723.72 | LQ8: 13795.34 | LR8: 20479 | LS8: 14606 | LT8: 34055.97 | LU8: 21740 | LV8: 12216 | LW8: 3219 | LX8: 7899 | LY8: 13011 | LZ8: 37103 | MA8: 19625 | MB8: 17465 | MC8: 16475 | MD8: 1152 | ME8: 16212 | MF8: 5885 | MG8: 12712 | MH8: 31694 | MI8: 52180 | MJ8: 19473 | MK8: 5939 | ML8: 14030 | MM8: 12145 | MN8: 16789 | MO8: 7811 | MP8: 21740 | MQ8: 12216 | MR8: 3219 | MS8: 7899 | MT8: 12211 | MU8: 15476 | MV8: 37807 | MW8: 35331 | MX8: 6623 | MY8: 3117 | MZ8: 12543 | NA8: 8877 | NB8: 7603 | NC8: 32821 | ND8: 5145 | NE8: 18048 | NF8: 9113 | NG8: 10671 | NH8: 14509 | NI8: 15155 | NJ8: 26642 | NK8: 25152 | NL8: 16869 | NM8: 9003 | NN8: 20795 | NO8: 10258 | NP8: 259954 | NQ8: 26844 | NR8: 29320 | NS8: 21867 | NT8: 13093 | NU8: 10893 | NV8: 46247 | NW8: 15265 | NX8: 28112 | NY8: 19721 | NZ8: 9229 | OA8: 2857 | OB8: 13665 | OC8: 13785 | OD8: 30795.76 | OE8: 27578 | OF8: 15064 | OG8: 18372 | OH8: 2201 | OI8: 33299.66 | OJ8: 17660.19 | OK8: 11681.31 | OL8: 25799.48 | OM8: 1970.4 | ON8: 17861.29 | OO8: 6490.65 | OP8: 13506.51 | OQ8: 31898.18 | OR8: 15502.94 | OS8: 34199.52 | OT8: 3003.72 | OU8: 0 | OV8: 3430.05 | OW8: 8685.62 | OX8: 19110.57 | OY8: 11575.33 | OZ8: 27069.54 | PA8: 15867.97 | PB8: 6049.51 | PC8: 6283.19 | PD8: 4545.62 | PE8: 4285.8 | PF8: 11276 | PG8: 18496.57 | PH8: 46134.88 | PI8: 15844 | PJ8: 3326 | PK8: 8838.78 | PL8: 4587.56 | PM8: 4766.15 | PN8: 38319.67 | PO8: 7376.6 | PP8: 3600.95 | PQ8: 303 | PR8: 2907 | PS8: 1813.94 | PT8: 4648.94 | PU8: 27387.92 | PV8: 7291 | PW8: 951.43 | PX8: 2371.86 | PY8: 5652.72 | PZ8: 6961.29 | QA8: 10574.45 | QB8: 11591.8 | QC8: 7332.29 | QD8: 1700.96 | QE8: 1827.53 | QF8: 3866.92 | QG8: 1633.25 | QH8: 7979.47 | QI8: 26595.75 | QJ8: 13645.73 | QK8: 11952.63 | QL8: 6335.63 | QM8: 10386.49 | QN8: 41081.71 | QO8: 14545 | QP8: 57025.12 | QQ8: 14652.89 | QR8: 29106.42 | QS8: 6647.28 | QT8: 10000 | QU8: 6580.61 | QV8: 14474.49 | QW8: 32399.69 | QX8: 16533.51 | QY8: 7364 | QZ8: 5834 | RA8: 13787.54 | RB8: 8734.72 | RC8: 11516 | RD8: 20183 | RE8: 38126.68 | RF8: 11709 | RG8: 3447 | RH8: 22558 | RI8: 29339 | RJ8: 21444 | RK8: 53781 | RL8: 11923.28 | RM8: 14649.97 | RN8: 6082.51 | RO8: 7916 | RP8: 15729 | RQ8: 19410.29 | RR8: 37163 | RS8: 18459.4 | RT8: 15109 | RU8: 7333 | RV8: 16464.52 | RW8: 5806.41 | RX8: 11714.48 | RY8: 44930.67 | RZ8: 21721.9 | SA8: 12665.39 | SB8: 4228.57 | SC8: 9540.78 | SD8: 33362.54 | SE8: 33362.54 | SF8: 30833.87 | SG8: 15004.01
C9: 3 PM - 4 PM | D9: 9981 | E9: 11601 | F9: 4754 | G9: 7411 | H9: 14774 | I9: 14633 | J9: 35917 | K9: 9981 | L9: 11601 | M9: 4754 | N9: 7411 | O9: 14774 | P9: 14633 | Q9: 35917 | R9: 9981 | S9: 11601 | T9: 4754 | U9: 7411 | V9: 14774 | W9: 14633 | X9: 35917 | Y9: 9981 | Z9: 11601 | AA9: 4754 | AB9: 7411 | AC9: 14774 | AD9: 14633 | AE9: 35917 | AF9: 9981 | AG9: 11601 | AH9: 4754 | AI9: 7411 | AJ9: 14774 | AK9: 14633 | AL9: 35917 | AM9: 9981 | AN9: 11601 | AO9: 4754 | AP9: 7411 | AQ9: 14774 | AR9: 14633 | AS9: 35917 | AT9: 9981 | AU9: 11601 | AV9: 4754 | AW9: 7411 | AX9: 14774 | AY9: 14633 | AZ9: 35917 | BA9: 9981 | BB9: 11601 | BC9: 4754 | BD9: 7411 | BE9: 14774 | BF9: 14633 | BG9: 35917 | BH9: 9981 | BI9: 11601 | BJ9: 4754 | BK9: 7411 | BL9: 14774 | BM9: 14633 | BN9: 35917 | BO9: 9981 | BP9: 11601 | BQ9: 4754 | BR9: 7411 | BS9: 14774 | BT9: 14633 | BU9: 35917 | BV9: 9981 | BW9: 11601 | BX9: 4754 | BY9: 7411 | BZ9: 14774 | CA9: 14633 | CB9: 35917 | CC9: 9981 | CD9: 11601 | CE9: 4754 | CF9: 7411 | CG9: 14774 | CH9: 14633 | CI9: 35917 | CJ9: 9981 | CK9: 11601 | CL9: 4754 | CM9: 7411 | CN9: 14774 | CO9: 14633 | CP9: 35917 | CQ9: 9981 | CR9: 11601 | CS9: 4754 | CT9: 7411 | CU9: 14774 | CV9: 14633 | CW9: 35917 | CX9: 9981 | CY9: 11601 | CZ9: 4754 | DA9: 7411 | DB9: 4754 | DC9: 3859 | DD9: 27804 | DE9: 11299 | DF9: 6712 | DG9: 475 | DH9: 9061 | DI9: 17719 | DJ9: 5220 | DK9: 29169 | DL9: 13167 | DM9: 24719 | DN9: 3824 | DO9: 13209 | DP9: 12205 | DQ9: 4684 | DR9: 32342 | DS9: 9612 | DT9: 8875 | DU9: 1984 | DV9: 7544 | DW9: 6066 | DX9: 2982 | DY9: 18647 | DZ9: 8854 | EA9: 16255 | EB9: 16254 | EC9: 19 | ED9: 5429 | EE9: 5730 | EF9: 26756 | EG9: 12229 | EH9: 17619.22 | EI9: 2603 | EJ9: 10737 | EK9: 8249 | EL9: 7469 | EM9: 28137 | EN9: 19986 | EO9: 7919 | EP9: 1958 | EQ9: 12204 | ER9: 10927 | ES9: 10032 | ET9: 22329.21 | EU9: 11403 | EV9: 17570.74 | EW9: 4688.92 | EX9: 12267 | EY9: 9945 | EZ9: 51601 | FA9: 38915 | FB9: 15392 | FC9: 4595.67 | FD9: 2915 | FE9: 570 | FF9: 3173 | FG9: 768 | FH9: 6335 | FI9: 4597 | FJ9: 6951 | FK9: 973 | FL9: 5323 | FM9: 14885 | FN9: 6973 | FO9: 38935 | FP9: 10332 | FQ9: 22031 | FR9: 2984 | FS9: 12128 | FT9: 15600 | FU9: 23409 | FV9: 47499 | FW9: 14739 | FX9: 15131 | FY9: 2693 | FZ9: 9225 | GA9: 21731 | GB9: 16333 | GC9: 24150 | GD9: 14657 | GE9: 9009 | GF9: 2395 | GG9: 10708 | GH9: 5065 | GI9: 19289 | GJ9: 32413 | GK9: 7165 | GL9: 11694.111 | GM9: 2524 | GN9: 12667 | GO9: 6634 | GP9: 15314 | GQ9: 51416 | GR9: 9759 | GS9: 5852.48 | GT9: 7495 | GU9: 10916 | GV9: 11953 | GW9: 15604 | GX9: 25619 | GY9: 7193 | GZ9: 18555 | HA9: 4754 | HB9: 7411 | HC9: 13352 | HD9: 15726 | HE9: 19419 | HF9: 23734 | HG9: 10125 | HH9: 5379 | HI9: 12055 | HJ9: 11983 | HK9: 12590 | HL9: 13238 | HM9: 7817 | HN9: 38916 | HO9: 1713 | HP9: 8380 | HQ9: 40466 | HR9: 9998 | HS9: 29816 | HT9: 13359 | HU9: 19242 | HV9: 1417 | HW9: 13994 | HX9: 14699 | HY9: 9180 | HZ9: 31766 | IA9: 11374 | IB9: 19095 | IC9: 8114 | ID9: 11104 | IE9: 21603 | IF9: 38358 | IG9: 44301 | IH9: 21498 | II9: 33753 | IJ9: 947 | IK9: 8198 | IL9: 17656 | IM9: 12886 | IN9: 26935 | IO9: 8692 | IP9: 12993 | IQ9: 3482 | IR9: 8365 | IS9: 14774 | IT9: 11601 | IU9: 14701 | IV9: 16705 | IW9: 10645 | IX9: 5965 | IY9: 13087 | IZ9: 23139 | JA9: 18883 | JB9: 35098 | JC9: 10638 | JD9: 8577 | JE9: 3741 | JF9: 9283 | JG9: 9635.59 | JH9: 23898 | JI9: 25888 | JJ9: 8023 | JK9: 19665 | JL9: 4820 | JM9: 17778 | JN9: 14692.58 | JO9: 22762 | JP9: 29916 | JQ9: 3834 | JR9: 2859 | JS9: 3160 | JT9: 9931 | JU9: 11893 | JV9: 16693 | JW9: 35917 | JX9: 9981 | JY9: 11601 | JZ9: 4239 | KA9: 9436 | KB9: 8910 | KC9: 17038 | KD9: 47016 | KE9: 14832 | KF9: 7783 | KG9: 5376 | KH9: 5895 | KI9: 22056 | KJ9: 17751 | KK9: 43386 | KL9: 16974 | KM9: 23007 | KN9: 1834 | KO9: 13422 | KP9: 11045 | KQ9: 6332 | KR9: 51219 | KS9: 12582 | KT9: 7960 | KU9: 8145 | KV9: 14409 | KW9: 7662.25 | KX9: 16159 | KY9: 42253 | KZ9: 8810 | LA9: 14581 | LB9: 4584.86 | LC9: 11005 | LD9: 15422 | LE9: 9651 | LF9: 23003 | LG9: 17051 | LH9: 13949 | LI9: 4260.09 | LJ9: 11545.28 | LK9: 8589.03 | LL9: 9467.79 | LM9: 39704.28 | LN9: 3451.86 | LO9: 12338.89 | LP9: 502.86 | LQ9: 14105.37 | LR9: 7593 | LS9: 7684 | LT9: 49513.89 | LU9: 9981 | LV9: 11601 | LW9: 4754 | LX9: 7411 | LY9: 14072 | LZ9: 31441 | MA9: 30204 | MB9: 12524 | MC9: 7166 | MD9: 5520 | ME9: 20996 | MF9: 7924 | MG9: 16477 | MH9: 39982 | MI9: 39764 | MJ9: 10345 | MK9: 8624 | ML9: 14168 | MM9: 15089 | MN9: 17733 | MO9: 11649 | MP9: 9981 | MQ9: 11601 | MR9: 4754 | MS9: 7411 | MT9: 14774 | MU9: 18007 | MV9: 46292 | MW9: 11660 | MX9: 10391 | MY9: 4137 | MZ9: 13109 | NA9: 12161 | NB9: 9587 | NC9: 42096 | ND9: 7763 | NE9: 13091 | NF9: 2165 | NG9: 11910 | NH9: 12155 | NI9: 33881 | NJ9: 32442 | NK9: 19192 | NL9: 12737 | NM9: 4447 | NN9: 16582 | NO9: 11864 | NP9: 13744 | NQ9: 20720 | NR9: 24276 | NS9: 7517 | NT9: 4597 | NU9: 8746 | NV9: 6366 | NW9: 20927 | NX9: 48182 | NY9: 5703 | NZ9: 26184 | OA9: 10345 | OB9: 9399 | OC9: 12529 | OD9: 4657.66 | OE9: 38090 | OF9: 14131 | OG9: 19705 | OH9: 6465 | OI9: 11311.78 | OJ9: 10027.71 | OK9: 11137.74 | OL9: 24619.16 | OM9: 6406.42 | ON9: 15797.82 | OO9: 4643.82 | OP9: 5806.43 | OQ9: 12382.52 | OR9: 14984.87 | OS9: 26301.14 | OT9: 1249.96 | OU9: 0 | OV9: 2041.91 | OW9: 5565.12 | OX9: 11161.29 | OY9: 18633.14 | OZ9: 38835.85 | PA9: 21283.39 | PB9: 5541.99 | PC9: 5319.91 | PD9: 2871.43 | PE9: 4133.25 | PF9: 23760 | PG9: 47207.25 | PH9: 21598.32 | PI9: 19697 | PJ9: 3104 | PK9: 6319.38 | PL9: 10790.98 | PM9: 23827.01 | PN9: 55873.23 | PO9: 16253.49 | PP9: 5392.38 | PQ9: 7410 | PR9: 10247 | PS9: 62746.04 | PT9: 13881.48 | PU9: 64366.32 | PV9: 29709 | PW9: 9152.91 | PX9: 9584.94 | PY9: 10098.36 | PZ9: 2924.84 | QA9: 12759.12 | QB9: 36761.83 | QC9: 10242.16 | QD9: 4749.1 | QE9: 7972.72 | QF9: 1538.36 | QG9: 4715.67 | QH9: 1920.09 | QI9: 22813.25 | QJ9: 16014.02 | QK9: 8612.82 | QL9: 3515.23 | QM9: 13979.48 | QN9: 11855 | QO9: 11257 | QP9: 43992.84 | QQ9: 17672.02 | QR9: 19867.79 | QS9: 2225.45 | QT9: 5188 | QU9: 7726.06 | QV9: 20192.53 | QW9: 36249.7 | QX9: 29223.53 | QY9: 13892 | QZ9: 1925 | RA9: 10703.38 | RB9: 21048.76 | RC9: 15165 | RD9: 15202 | RE9: 4740.44 | RF9: 8987 | RG9: 3292 | RH9: 16510 | RI9: 25477 | RJ9: 9503 | RK9: 36042 | RL9: 16410.99 | RM9: 12008.93 | RN9: 1331.17 | RO9: 11895 | RP9: 13118 | RQ9: 11502.6 | RR9: 35175.19 | RS9: 25484.38 | RT9: 18191 | RU9: 19398 | RV9: 9601.99 | RW9: 8323.46 | RX9: 16307.98 | RY9: 50123.17 | RZ9: 13747.43 | SA9: 20727.99 | SB9: 2573.34 | SC9: 7130.06 | SD9: 15373.15 | SE9: 15373.15 | SF9: 56566.78 | SG9: 13516.71
C10: 4 PM - 5 PM | D10: 11259 | E10: 6767 | F10: 15372 | G10: 6438 | H10: 13387 | I10: 14651 | J10: 67854 | K10: 11259 | L10: 6767 | M10: 15372 | N10: 6438 | O10: 13387 | P10: 14651 | Q10: 67854 | R10: 11259 | S10: 6767 | T10: 15372 | U10: 6438 | V10: 13387 | W10: 14651 | X10: 67854 | Y10: 11259 | Z10: 6767 | AA10: 15372 | AB10: 6438 | AC10: 13387 | AD10: 14651 | AE10: 67854 | AF10: 11259 | AG10: 6767 | AH10: 15372 | AI10: 6438 | AJ10: 13387 | AK10: 14651 | AL10: 67854 | AM10: 11259 | AN10: 6767 | AO10: 15372 | AP10: 6438 | AQ10: 13387 | AR10: 14651 | AS10: 67854 | AT10: 11259 | AU10: 6767 | AV10: 15372 | AW10: 6438 | AX10: 13387 | AY10: 14651 | AZ10: 67854 | BA10: 11259 | BB10: 6767 | BC10: 15372 | BD10: 6438 | BE10: 13387 | BF10: 14651 | BG10: 67854 | BH10: 11259 | BI10: 6767 | BJ10: 15372 | BK10: 6438 | BL10: 13387 | BM10: 14651 | BN10: 67854 | BO10: 11259 | BP10: 6767 | BQ10: 15372 | BR10: 6438 | BS10: 13387 | BT10: 14651 | BU10: 67854 | BV10: 11259 | BW10: 6767 | BX10: 15372 | BY10: 6438 | BZ10: 13387 | CA10: 14651 | CB10: 67854 | CC10: 11259 | CD10: 6767 | CE10: 15372 | CF10: 6438 | CG10: 13387 | CH10: 14651 | CI10: 67854 | CJ10: 11259 | CK10: 6767 | CL10: 15372 | CM10: 6438 | CN10: 13387 | CO10: 14651 | CP10: 67854 | CQ10: 11259 | CR10: 6767 | CS10: 15372 | CT10: 6438 | CU10: 13387 | CV10: 14651 | CW10: 67854 | CX10: 11259 | CY10: 6767 | CZ10: 15372 | DA10: 6438 | DB10: 15372 | DC10: 2545 | DD10: 16621 | DE10: 8116 | DF10: 9953 | DG10: 3921 | DH10: 3709 | DI10: 22060 | DJ10: 13760 | DK10: 14703 | DL10: 4511 | DM10: 10090 | DN10: 5739 | DO10: 11280 | DP10: 5112 | DQ10: 10742 | DR10: 24680 | DS10: 6709 | DT10: 10990 | DU10: 1459 | DV10: 5910 | DW10: 6355 | DX10: 10734 | DY10: 42505 | DZ10: 16585 | EA10: 11965 | EB10: 11965 | EC10: 2583 | ED10: 13185 | EE10: 4712 | EF10: 24481 | EG10: 8518 | EH10: 7394 | EI10: 1803 | EJ10: 8260 | EK10: 8119 | EL10: 13716 | EM10: 49176 | EN10: 6856 | EO10: 8814 | EP10: 6784 | EQ10: 7920 | ER10: 7126 | ES10: 9486 | ET10: 39564.62 | EU10: 8136 | EV10: 11090.49 | EW10: 6077.91 | EX10: 8719 | EY10: 11080 | EZ10: 26054 | FA10: 43619 | FB10: 10317 | FC10: 6238.54 | FD10: 4849 | FE10: 1426 | FF10: 3792 | FG10: 4618 | FH10: 5414 | FI10: 522 | FJ10: 4219 | FK10: 5998 | FL10: 11108 | FM10: 7572 | FN10: 17248 | FO10: 16332 | FP10: 8115 | FQ10: 24617 | FR10: 30682 | FS10: 11801 | FT10: 17331 | FU10: 7607 | FV10: 33082 | FW10: 10321 | FX10: 6449 | FY10: 2344 | FZ10: 3599 | GA10: 8699 | GB10: 13663 | GC10: 19478 | GD10: 11009 | GE10: 24076 | GF10: 2573 | GG10: 6111 | GH10: 4006 | GI10: 13538 | GJ10: 53397 | GK10: 13439 | GL10: 20078.96 | GM10: 3475 | GN10: 10877 | GO10: 9493 | GP10: 12500 | GQ10: 56962 | GR10: 13489 | GS10: 10601.05 | GT10: 2144 | GU10: 22339 | GV10: 10836 | GW10: 11637 | GX10: 31154 | GY10: 8294 | GZ10: 7758 | HA10: 15372 | HB10: 6438 | HC10: 6078 | HD10: 17237 | HE10: 32886 | HF10: 13408 | HG10: 10139 | HH10: 5525 | HI10: 18399 | HJ10: 15658 | HK10: 15449 | HL10: 11543 | HM10: 13064 | HN10: 11314 | HO10: 10853 | HP10: 18043 | HQ10: 13493 | HR10: 11717 | HS10: 40803 | HT10: 15324 | HU10: 11013 | HV10: 1350 | HW10: 9596 | HX10: 9771 | HY10: 12665 | HZ10: 46459 | IA10: 14534 | IB10: 10627 | IC10: 5168 | ID10: 11095 | IE10: 8449 | IF10: 20473 | IG10: 53319 | IH10: 13120 | II10: 9624 | IJ10: 4046 | IK10: 6502 | IL10: 13494 | IM10: 12455 | IN10: 55016 | IO10: 13629 | IP10: 13815 | IQ10: 6261 | IR10: 6375 | IS10: 13387 | IT10: 6767 | IU10: 21026 | IV10: 8025 | IW10: 15629 | IX10: 6573 | IY10: 16814 | IZ10: 1012 | JA10: 19898 | JB10: 45464 | JC10: 9209 | JD10: 14778 | JE10: 9549 | JF10: 11021 | JG10: 21618.1 | JH10: 5209 | JI10: 31912 | JJ10: 9892 | JK10: 8938 | JL10: 4465 | JM10: 14024 | JN10: 6367.97 | JO10: 34859 | JP10: 52468 | JQ10: 13369 | JR10: 10789 | JS10: 2401 | JT10: 7017 | JU10: 4733 | JV10: 28310 | JW10: 67854 | JX10: 11259 | JY10: 6767 | JZ10: 4045 | KA10: 14441 | KB10: 15011 | KC10: 19252 | KD10: 61504 | KE10: 5927 | KF10: 12767 | KG10: 7251 | KH10: 13778 | KI10: 12495 | KJ10: 13464 | KK10: 49147 | KL10: 12034 | KM10: 10057 | KN10: 8375 | KO10: 13317 | KP10: 9238 | KQ10: 10021 | KR10: 88613 | KS10: 13226 | KT10: 15041 | KU10: 19738 | KV10: 17116 | KW10: 6492.03 | KX10: 18633 | KY10: 73063 | KZ10: 5883 | LA10: 21603 | LB10: 2726.84 | LC10: 15760 | LD10: 10532 | LE10: 9919 | LF10: 45220 | LG10: 21207 | LH10: 11292 | LI10: 4139.66 | LJ10: 14069.51 | LK10: 14404.33 | LL10: 11434.63 | LM10: 55388.45 | LN10: 8349.19 | LO10: 17339.6 | LP10: 13050.15 | LQ10: 11830.21 | LR10: 14860 | LS10: 18454 | LT10: 53358.31 | LU10: 11259 | LV10: 6767 | LW10: 15372 | LX10: 6438 | LY10: 4139 | LZ10: 26225 | MA10: 57372 | MB10: 9614 | MC10: 13150 | MD10: 6712 | ME10: 10703 | MF10: 16305 | MG10: 98479 | MH10: 53921 | MI10: 10990 | MJ10: 12297 | MK10: 5690 | ML10: 7302 | MM10: 9870 | MN10: 14930 | MO10: 21792 | MP10: 11259 | MQ10: 6767 | MR10: 15372 | MS10: 6438 | MT10: 13387 | MU10: 16980 | MV10: 66393 | MW10: 23256 | MX10: 2215 | MY10: 5202 | MZ10: 16455 | NA10: 5141 | NB10: 25948 | NC10: 47291 | ND10: 7023 | NE10: 28971 | NF10: 4994 | NG10: 11125 | NH10: 17487 | NI10: 17022 | NJ10: 52078 | NK10: 16067 | NL10: 13053 | NM10: 7954 | NN10: 9149 | NO10: 13487 | NP10: 11374 | NQ10: 29468 | NR10: 23767 | NS10: 13743 | NT10: 7513 | NU10: 6505 | NV10: 17869 | NW10: 14868 | NX10: 69110 | NY10: 9463 | NZ10: 10872 | OA10: 6527 | OB10: 14670 | OC10: 14279 | OD10: 15316.46 | OE10: 47978 | OF10: 10514 | OG10: 11070 | OH10: 3923 | OI10: 10824.25 | OJ10: 9656.36 | OK10: 14281.62 | OL10: 40521.26 | OM10: 3053.77 | ON10: 8249.7 | OO10: 1370.22 | OP10: 7498.61 | OQ10: 29759.66 | OR10: 13816.97 | OS10: 45974.94 | OT10: 0 | OU10: 5072.11 | OV10: 2026.5 | OW10: 24450.83 | OX10: 15074.78 | OY10: 20195.84 | OZ10: 57375.79 | PA10: 15663.96 | PB10: 14528.4 | PC10: 2874.98 | PD10: 8799.57 | PE10: 3835.68 | PF10: 12084 | PG10: 54663.19 | PH10: 22454.72 | PI10: 31145 | PJ10: 9411 | PK10: 23984.15 | PL10: 17818.26 | PM10: 14310.36 | PN10: 92875.7 | PO10: 21207.94 | PP10: 23523.36 | PQ10: 7291 | PR10: 11804 | PS10: 13243.62 | PT10: 17615.85 | PU10: 74709.43 | PV10: 28821 | PW10: 14589.16 | PX10: 15611.11 | PY10: 22093.25 | PZ10: 23163.45 | QA10: 23473.85 | QB10: 51590.87 | QC10: 11330.46 | QD10: 14999.56 | QE10: 13869.77 | QF10: 2997.4 | QG10: 9031.26 | QH10: 1855.84 | QI10: 35378.38 | QJ10: 18915.16 | QK10: 11094.18 | QL10: 4546.83 | QM10: 12480.54 | QN10: 10553 | QO10: 16761 | QP10: 49565.81 | QQ10: 31039.42 | QR10: 9452.81 | QS10: 4669.18 | QT10: 16382 | QU10: 12386.84 | QV10: 18912.06 | QW10: 46752.18 | QX10: 11161.11 | QY10: 8990 | QZ10: 7134 | RA10: 11624 | RB10: 8930.13 | RC10: 16892 | RD10: 24137 | RE10: 16480.2 | RF10: 18479 | RG10: 6024 | RH10: 17026 | RI10: 7700 | RJ10: 8298 | RK10: 41832 | RL10: 16260.09 | RM10: 11317.92 | RN10: 2758.1 | RO10: 25222 | RP10: 7470 | RQ10: 14789.64 | RR10: 50547.68 | RS10: 20723 | RT10: 26260 | RU10: 29781 | RV10: 17498.37 | RW10: 19957.32 | RX10: 7805.3 | RY10: 49920.06 | RZ10: 15590.3 | SA10: 7299.16 | SB10: 7020.35 | SC10: 11738.2 | SD10: 15228.31 | SE10: 15228.31 | SF10: 61812.19 | SG10: 18994.27
C11: 5 PM - 6 PM | D11: 6524 | E11: 10031 | F11: 21761 | G11: 10245 | H11: 14046 | I11: 12374 | J11: 70751 | K11: 6524 | L11: 10031 | M11: 21761 | N11: 10245 | O11: 14046 | P11: 12374 | Q11: 70751 | R11: 6524 | S11: 10031 | T11: 21761 | U11: 10245 | V11: 14046 | W11: 12374 | X11: 70751 | Y11: 6524 | Z11: 10031 | AA11: 21761 | AB11: 10245 | AC11: 14046 | AD11: 12374 | AE11: 70751 | AF11: 6524 | AG11: 10031 | AH11: 21761 | AI11: 10245 | AJ11: 14046 | AK11: 12374 | AL11: 70751 | AM11: 6524 | AN11: 10031 | AO11: 21761 | AP11: 10245 | AQ11: 14046 | AR11: 12374 | AS11: 70751 | AT11: 6524 | AU11: 10031 | AV11: 21761 | AW11: 10245 | AX11: 14046 | AY11: 12374 | AZ11: 70751 | BA11: 6524 | BB11: 10031 | BC11: 21761 | BD11: 10245 | BE11: 14046 | BF11: 12374 | BG11: 70751 | BH11: 6524 | BI11: 10031 | BJ11: 21761 | BK11: 10245 | BL11: 14046 | BM11: 12374 | BN11: 70751 | BO11: 6524 | BP11: 10031 | BQ11: 21761 | BR11: 10245 | BS11: 14046 | BT11: 12374 | BU11: 70751 | BV11: 6524 | BW11: 10031 | BX11: 21761 | BY11: 10245 | BZ11: 14046 | CA11: 12374 | CB11: 70751 | CC11: 6524 | CD11: 10031 | CE11: 21761 | CF11: 10245 | CG11: 14046 | CH11: 12374 | CI11: 70751 | CJ11: 6524 | CK11: 10031 | CL11: 21761 | CM11: 10245 | CN11: 14046 | CO11: 12374 | CP11: 70751 | CQ11: 6524 | CR11: 10031 | CS11: 21761 | CT11: 10245 | CU11: 14046 | CV11: 12374 | CW11: 70751 | CX11: 6524 | CY11: 10031 | CZ11: 21761 | DA11: 10245 | DB11: 21761 | DC11: 6822 | DD11: 35430 | DE11: 4346 | DF11: 14070 | DG11: 10256 | DH11: 11171 | DI11: 9510 | DJ11: 11392 | DK11: 12138 | DL11: 13592 | DM11: 10224 | DN11: 4917 | DO11: 12742 | DP11: 5429 | DQ11: 19326 | DR11: 4737 | DS11: 14424 | DT11: 10828 | DU11: 6557 | DV11: 16136 | DW11: 6476 | DX11: 13794 | DY11: 47334 | DZ11: 30174 | EA11: 14997 | EB11: 14496 | EC11: 6418 | ED11: 14393 | EE11: 8798 | EF11: 47596 | EG11: 12272 | EH11: 14395 | EI11: 12447 | EJ11: 11047 | EK11: 5162 | EL11: 18690 | EM11: 43877 | EN11: 13905 | EO11: 17755 | EP11: 9398 | EQ11: 22528 | ER11: 11710 | ES11: 18962 | ET11: 43666.81 | EU11: 8699.21 | EV11: 16214.45 | EW11: 14490.13 | EX11: 14772 | EY11: 9483 | EZ11: 12795 | FA11: 47654 | FB11: 15208 | FC11: 4648.75 | FD11: 14399 | FE11: 7192 | FF11: 885 | FG11: 5437 | FH11: 8904 | FI11: 4233 | FJ11: 3088 | FK11: 5923 | FL11: 11094 | FM11: 12585 | FN11: 21116 | FO11: 24049 | FP11: 16356 | FQ11: 11028 | FR11: 10011 | FS11: 13807 | FT11: 22272 | FU11: 10520 | FV11: 53057 | FW11: 16659 | FX11: 16523 | FY11: 8055 | FZ11: 13500 | GA11: 14542 | GB11: 16771 | GC11: 37597 | GD11: 16727 | GE11: 13459 | GF11: 8211 | GG11: 13187 | GH11: 12426 | GI11: 13742 | GJ11: 51578 | GK11: 8854 | GL11: 10860.34 | GM11: 9798 | GN11: 10300 | GO11: 11263 | GP11: 18382 | GQ11: 73694 | GR11: 17030 | GS11: 15282.34 | GT11: 8254 | GU11: 12303 | GV11: 7962 | GW11: 14354 | GX11: 47531 | GY11: 24663 | GZ11: 12127 | HA11: 21761 | HB11: 10245 | HC11: 10332 | HD11: 14422 | HE11: 44885 | HF11: 6794 | HG11: 13076 | HH11: 11440 | HI11: 16030 | HJ11: 9571 | HK11: 18865 | HL11: 35945 | HM11: 13598 | HN11: 24005 | HO11: 5952 | HP11: 15426 | HQ11: 12204 | HR11: 21891 | HS11: 65486 | HT11: 9803 | HU11: 13112 | HV11: 7377 | HW11: 15819 | HX11: 25805 | HY11: 14439 | HZ11: 66931 | IA11: 19206 | IB11: 11197 | IC11: 12093 | ID11: 14416 | IE11: 22355 | IF11: 20236 | IG11: 68753 | IH11: 17077 | II11: 11888 | IJ11: 13659 | IK11: 12866 | IL11: 20417 | IM11: 28198 | IN11: 70784 | IO11: 24522 | IP11: 8979 | IQ11: 9842 | IR11: 18025 | IS11: 14046 | IT11: 10031 | IU11: 23967 | IV11: 10809 | IW11: 10785 | IX11: 14017 | IY11: 12460 | IZ11: 16123 | JA11: 14110 | JB11: 71447 | JC11: 19721 | JD11: 23046 | JE11: 31117 | JF11: 23211 | JG11: 6782.19 | JH11: 16505 | JI11: 70053 | JJ11: 14579 | JK11: 8950 | JL11: 11636 | JM11: 7933 | JN11: 8718.95 | JO11: 14955 | JP11: 62379 | JQ11: 7795 | JR11: 16187 | JS11: 10185 | JT11: 13040 | JU11: 23360 | JV11: 14795 | JW11: 70751 | JX11: 6524 | JY11: 10031 | JZ11: 7644 | KA11: 24272 | KB11: 7132 | KC11: 25086 | KD11: 66300 | KE11: 11633 | KF11: 18856 | KG11: 13650 | KH11: 12312 | KI11: 10282 | KJ11: 10793 | KK11: 57716 | KL11: 12662 | KM11: 22708 | KN11: 13741 | KO11: 22169 | KP11: 29451 | KQ11: 11923 | KR11: 62984 | KS11: 14485 | KT11: 21549 | KU11: 15602 | KV11: 26260 | KW11: 11158.51 | KX11: 35353 | KY11: 89599 | KZ11: 14852 | LA11: 10642 | LB11: 14088.41 | LC11: 21375 | LD11: 4205 | LE11: 17602 | LF11: 76516 | LG11: 20659 | LH11: 22864 | LI11: 13887.81 | LJ11: 26696.81 | LK11: 11325.52 | LL11: 20765.64 | LM11: 82303.31 | LN11: 18678.02 | LO11: 9958.6 | LP11: 7434.21 | LQ11: 18634.99 | LR11: 21189 | LS11: 18587 | LT11: 78851.33 | LU11: 6524 | LV11: 10031 | LW11: 21761 | LX11: 10245 | LY11: 6314 | LZ11: 21318 | MA11: 88949 | MB11: 14968 | MC11: 13813 | MD11: 8747 | ME11: 24645 | MF11: 17072 | MG11: 18694 | MH11: 91058 | MI11: 24769 | MJ11: 12648 | MK11: 15619 | ML11: 26861 | MM11: 8320 | MN11: 11763 | MO11: 37907 | MP11: 6524 | MQ11: 10031 | MR11: 21761 | MS11: 10245 | MT11: 14046 | MU11: 28229 | MV11: 90339 | MW11: 12593 | MX11: 7232 | MY11: 9288 | MZ11: 15919 | NA11: 14045 | NB11: 35531 | NC11: 73114 | ND11: 15525 | NE11: 20423 | NF11: 4785 | NG11: 225154 | NH11: 12805 | NI11: 15159 | NJ11: 72896 | NK11: 13640 | NL11: 2982 | NM11: 10379 | NN11: 13117 | NO11: 10580 | NP11: 17385 | NQ11: 38550 | NR11: 11905 | NS11: 12374 | NT11: 7349 | NU11: 6271 | NV11: 23037 | NW11: 17623 | NX11: 64465 | NY11: 8727 | NZ11: 14120 | OA11: 9422 | OB11: 22317 | OC11: 14755 | OD11: 22709.53 | OE11: 52498 | OF11: 13175 | OG11: 21429 | OH11: 10162 | OI11: 13669.14 | OJ11: 3000.96 | OK11: 22062.12 | OL11: 71687.03 | OM11: 3692.04 | ON11: 10391.02 | OO11: 13293.59 | OP11: 10980.79 | OQ11: 9801.63 | OR11: 15838.61 | OS11: 57033.07 | OT11: 4296.63 | OU11: 848.4 | OV11: 3209.78 | OW11: 24429.35 | OX11: 8960.28 | OY11: 15389.43 | OZ11: 56202.9 | PA11: 20868.39 | PB11: 8172.66 | PC11: 9104.75 | PD11: 18501.9 | PE11: 2918.95 | PF11: 3787 | PG11: 50187.08 | PH11: 34557.95 | PI11: 1044 | PJ11: 17286 | PK11: 28888.86 | PL11: 23032.28 | PM11: 33468.79 | PN11: 51269.69 | PO11: 9856.88 | PP11: 24851.7 | PQ11: 22728 | PR11: 18278 | PS11: 24745.46 | PT11: 28996.19 | PU11: 55080.27 | PV11: 51194 | PW11: 35221.13 | PX11: 23599.21 | PY11: 40744.61 | PZ11: 33199.16 | QA11: 28141.19 | QB11: 71685.19 | QC11: 34270.29 | QD11: 29943.44 | QE11: 17251.59 | QF11: 6284.24 | QG11: 12956.38 | QH11: 7728.84 | QI11: 41920.94 | QJ11: 15494.87 | QK11: 18789.09 | QL11: 17676 | QM11: 13747.62 | QN11: 5764 | QO11: 19744 | QP11: 76715.07 | QQ11: 32844.99 | QR11: 17933.05 | QS11: 13918.96 | QT11: 17446 | QU11: 11551.6 | QV11: 18317.3 | QW11: 55584.06 | QX11: 17425.78 | QY11: 19201 | QZ11: 7532 | RA11: 17124.5 | RB11: 12945.89 | RC11: 20591 | RD11: 34004 | RE11: 17609.62 | RF11: 8308 | RG11: 14196 | RH11: 17309 | RI11: 5458 | RJ11: 19442 | RK11: 51540 | RL11: 24107.17 | RM11: 18533.41 | RN11: 9071.78 | RO11: 20924 | RP11: 8946 | RQ11: 29195.59 | RR11: 63277.64 | RS11: 22715 | RT11: 12622 | RU11: 33142 | RV11: 23238.8 | RW11: 17761.57 | RX11: 21818.01 | RY11: 73528.45 | RZ11: 26601.84 | SA11: 11842.52 | SB11: 5170.04 | SC11: 8998.61 | SD11: 21014.26 | SE11: 21014.26 | SF11: 53092.79 | SG11: 15538.6
C12: 6 PM - 7 PM | D12: 32815 | E12: 14023 | F12: 31527 | G12: 12536 | H12: 18566 | I12: 19275 | J12: 82264 | K12: 32815 | L12: 14023 | M12: 31527 | N12: 12536 | O12: 18566 | P12: 19275 | Q12: 82264 | R12: 32815 | S12: 14023 | T12: 31527 | U12: 12536 | V12: 18566 | W12: 19275 | X12: 82264 | Y12: 32815 | Z12: 14023 | AA12: 31527 | AB12: 12536 | AC12: 18566 | AD12: 19275 | AE12: 82264 | AF12: 32815 | AG12: 14023 | AH12: 31527 | AI12: 12536 | AJ12: 18566 | AK12: 19275 | AL12: 82264 | AM12: 32815 | AN12: 14023 | AO12: 31527 | AP12: 12536 | AQ12: 18566 | AR12: 19275 | AS12: 82264 | AT12: 32815 | AU12: 14023 | AV12: 31527 | AW12: 12536 | AX12: 18566 | AY12: 19275 | AZ12: 82264 | BA12: 32815 | BB12: 14023 | BC12: 31527 | BD12: 12536 | BE12: 18566 | BF12: 19275 | BG12: 82264 | BH12: 32815 | BI12: 14023 | BJ12: 31527 | BK12: 12536 | BL12: 18566 | BM12: 19275 | BN12: 82264 | BO12: 32815 | BP12: 14023 | BQ12: 31527 | BR12: 12536 | BS12: 18566 | BT12: 19275 | BU12: 82264 | BV12: 32815 | BW12: 14023 | BX12: 31527 | BY12: 12536 | BZ12: 18566 | CA12: 19275 | CB12: 82264 | CC12: 32815 | CD12: 14023 | CE12: 31527 | CF12: 12536 | CG12: 18566 | CH12: 19275 | CI12: 82264 | CJ12: 32815 | CK12: 14023 | CL12: 31527 | CM12: 12536 | CN12: 18566 | CO12: 19275 | CP12: 82264 | CQ12: 32815 | CR12: 14023 | CS12: 31527 | CT12: 12536 | CU12: 18566 | CV12: 19275 | CW12: 82264 | CX12: 32815 | CY12: 14023 | CZ12: 31527 | DA12: 12536 | DB12: 31527 | DC12: 12913 | DD12: 33834 | DE12: 4934 | DF12: 9022 | DG12: 8893 | DH12: 11274 | DI12: 12658 | DJ12: 13009 | DK12: 49614 | DL12: 23123 | DM12: 17024 | DN12: 14390 | DO12: 24607 | DP12: 11970 | DQ12: 25727 | DR12: 51370 | DS12: 19958 | DT12: 14644 | DU12: 9987 | DV12: 16404 | DW12: 8428 | DX12: 27744 | DY12: 77068 | DZ12: 12106 | EA12: 14747 | EB12: 14746 | EC12: 5734 | ED12: 20154 | EE12: 9933 | EF12: 72387 | EG12: 9557 | EH12: 12396 | EI12: 15769 | EJ12: 25277 | EK12: 5285 | EL12: 16690 | EM12: 71778 | EN12: 19335 | EO12: 19296 | EP12: 11333 | EQ12: 23788 | ER12: 17600 | ES12: 28030 | ET12: 60596.97 | EU12: 12208.75 | EV12: 21709.69 | EW12: 13659.66 | EX12: 30092 | EY12: 7437 | EZ12: 17378 | FA12: 59447 | FB12: 19958 | FC12: 6758.8 | FD12: 14756 | FE12: 2036 | FF12: 22299 | FG12: 11290 | FH12: 35866 | FI12: 9169 | FJ12: 19248 | FK12: 12934 | FL12: 12234 | FM12: 13014 | FN12: 22301 | FO12: 39951 | FP12: 20976 | FQ12: 20736 | FR12: 17114 | FS12: 19561 | FT12: 22098 | FU12: 23858 | FV12: 55641 | FW12: 17302 | FX12: 23105 | FY12: 14281 | FZ12: 14036 | GA12: 20615 | GB12: 30045 | GC12: 69839 | GD12: 18590 | GE12: 20544 | GF12: 36967 | GG12: 20414 | GH12: 12475 | GI12: 28418 | GJ12: 82890 | GK12: 18098 | GL12: 18533.98 | GM12: 12507 | GN12: 17370 | GO12: 15847 | GP12: 31579 | GQ12: 5305 | GR12: 28941 | GS12: 18801.55 | GT12: 13500 | GU12: 16749 | GV12: 14360 | GW12: 13419 | GX12: 96883 | GY12: 20293 | GZ12: 24184 | HA12: 31527 | HB12: 12536 | HC12: 16951 | HD12: 20399 | HE12: 70357 | HF12: 18554 | HG12: 20445 | HH12: 12807 | HI12: 22001 | HJ12: 21034 | HK12: 21683 | HL12: 45137 | HM12: 12208 | HN12: 20687 | HO12: 22582 | HP12: 19872 | HQ12: 15004 | HR12: 18702 | HS12: 71259 | HT12: 19993 | HU12: 14962 | HV12: 16750 | HW12: 18618 | HX12: 27496 | HY12: 20514 | HZ12: 100700 | IA12: 15613 | IB12: 20058 | IC12: 17492 | ID12: 27441 | IE12: 16884 | IF12: 14238 | IG12: 79905 | IH12: 23135 | II12: 16163 | IJ12: 18034 | IK12: 22008 | IL12: 14465 | IM12: 25593 | IN12: 91087 | IO12: 21601 | IP12: 28709 | IQ12: 17056 | IR12: 30061 | IS12: 18566 | IT12: 14023 | IU12: 33783 | IV12: 8880 | IW12: 8032 | IX12: 15573 | IY12: 24764 | IZ12: 13279 | JA12: 25484 | JB12: 98130 | JC12: 26132 | JD12: 23300 | JE12: 21618 | JF12: 24043 | JG12: 23851.64 | JH12: 17807 | JI12: 94947 | JJ12: 23270 | JK12: 30367 | JL12: 20399 | JM12: 20085 | JN12: 17072.4 | JO12: 23384 | JP12: 76024 | JQ12: 15117 | JR12: 15617 | JS12: 23535 | JT12: 15612 | JU12: 19029 | JV12: 21811 | JW12: 82264 | JX12: 32815 | JY12: 14023 | JZ12: 20671 | KA12: 29658 | KB12: 21790 | KC12: 14639 | KD12: 88333 | KE12: 22646 | KF12: 17897 | KG12: 13566 | KH12: 190224 | KI12: 12039 | KJ12: 31586 | KK12: 82869 | KL12: 10815 | KM12: 24970 | KN12: 14252 | KO12: 29411 | KP12: 26276 | KQ12: 28666 | KR12: 87880 | KS12: 13773 | KT12: 25324 | KU12: 10323 | KV12: 19722 | KW12: 7700.77 | KX12: 40467 | KY12: 88509 | KZ12: 31696 | LA12: 19402 | LB12: 27046.06 | LC12: 36901 | LD12: 17671 | LE12: 32412 | LF12: 77633 | LG12: 16800 | LH12: 10881 | LI12: 23153.1 | LJ12: 22132.48 | LK12: 25147.96 | LL12: 22770 | LM12: 95868.6 | LN12: 17364.41 | LO12: 30095.73 | LP12: 15483.98 | LQ12: 27987.54 | LR12: 38617 | LS12: 40421 | LT12: 81805.37 | LU12: 32815 | LV12: 14023 | LW12: 31527 | LX12: 12536 | LY12: 20547 | LZ12: 28197 | MA12: 84516 | MB12: 10196 | MC12: 25318 | MD12: 22570 | ME12: 27885 | MF12: 13034 | MG12: 21788 | MH12: 66194 | MI12: 17447 | MJ12: 12646 | MK12: 22438 | ML12: 23774 | MM12: 11014 | MN12: 30910 | MO12: 51433 | MP12: 32815 | MQ12: 14023 | MR12: 31527 | MS12: 12536 | MT12: 18566 | MU12: 32627 | MV12: 50525 | MW12: 24536 | MX12: 17037 | MY12: 15643 | MZ12: 26850 | NA12: 13505 | NB12: 31653 | NC12: 102716 | ND12: 30837 | NE12: 22276 | NF12: 12956 | NG12: 19230 | NH12: 17884 | NI12: 20711 | NJ12: 54428 | NK12: 32324 | NL12: 20080 | NM12: 27417 | NN12: 20307 | NO12: 16232 | NP12: 17473 | NQ12: 76013 | NR12: 17417 | NS12: 28228 | NT12: 10015 | NU12: 13262 | NV12: 16206 | NW12: 22959 | NX12: 54406 | NY12: 17759 | NZ12: 34342 | OA12: 15723 | OB12: 19990 | OC12: 18394 | OD12: 25924.01 | OE12: 63523 | OF12: 12803 | OG12: 31471 | OH12: 20489 | OI12: 18213.41 | OJ12: 12645.11 | OK12: 25078.32 | OL12: 51859.47 | OM12: 6852.31 | ON12: 14431.7 | OO12: 15947.63 | OP12: 21694.62 | OQ12: 22282.69 | OR12: 16899.82 | OS12: 54257.47 | OT12: 10556.1 | OU12: 10315.49 | OV12: 13840.95 | OW12: 28086.96 | OX12: 14997.31 | OY12: 26777.41 | OZ12: 60731 | PA12: 16636.26 | PB12: 2960.61 | PC12: 4296.2 | PD12: 1846.41 | PE12: 14480.81 | PF12: 6214 | PG12: 11388.41 | PH12: 8373.4 | PI12: 13590 | PJ12: 4544 | PK12: 5206.91 | PL12: 2277.58 | PM12: 4824.78 | PN12: 21371.62 | PO12: 10868.5 | PP12: 16968.51 | PQ12: 2673 | PR12: 2080 | PS12: 21028.06 | PT12: 8567.7 | PU12: 18820.21 | PV12: 3006 | PW12: 5512.29 | PX12: 14386.58 | PY12: 10866.95 | PZ12: 7154.38 | QA12: 7138.7 | QB12: 26726.49 | QC12: 11384.79 | QD12: 9252.22 | QE12: 10803.12 | QF12: 8135.15 | QG12: 18731.15 | QH12: 42519.32 | QI12: 53746.84 | QJ12: 13150.56 | QK12: 23679.11 | QL12: 15484 | QM12: 34055.47 | QN12: 10154 | QO12: 19622 | QP12: 88521.39 | QQ12: 42646.09 | QR12: 31887 | QS12: 17379.76 | QT12: 15073 | QU12: 19322.15 | QV12: 21295.16 | QW12: 77660.18 | QX12: 25051.58 | QY12: 14488 | QZ12: 27044 | RA12: 29862.17 | RB12: 19720.71 | RC12: 18875 | RD12: 68065 | RE12: 22424.03 | RF12: 19428 | RG12: 16336 | RH12: 24583 | RI12: 10191 | RJ12: 27527 | RK12: 74280 | RL12: 18212.26 | RM12: 19585.09 | RN12: 13281.73 | RO12: 30448 | RP12: 14146 | RQ12: 31526.74 | RR12: 65950.08 | RS12: 32726 | RT12: 16346 | RU12: 18089 | RV12: 30556.89 | RW12: 13052.81 | RX12: 17854.83 | RY12: 78737.6 | RZ12: 22529.82 | SA12: 22847.44 | SB12: 21294.62 | SC12: 26565.17 | SD12: 27370.47 | SE12: 27370.67 | SF12: 90056.26 | SG12: 33244.22
